Workbook

Sheet Cover
A1: ASPSI–DOH UHC CAPI — UAT Ticket Register
A2: GitHub issue export by UAT round, instrument, and resolution
A4: Prepared for | B4: ASPSI (for DOH documentation)
A5: Prepared by | B5: Carl Patrick L. Reyes — Data Programmer
A6: Generated | B6: 2026-06-29
A7: Source | B7: GitHub — cplreyes/ASPSI-DOH-UHC-CAPI-Development (Issues)
A8: Total issues in repo | B8: 736
A9: UAT-round tickets | B9: 381
A10: Non-round (dev/backlog) | B10: 355
A11: Current open issues | B11: 0
A13: UAT round legend
A14: R1 / R2 / R3 | B14: F2 PWA (Healthcare-Worker self-administered) — labels round:1 / round:2(+from-uat-round-2) / round:3(+from-uat-round-3)
A15: R4 | B15: CAPI F1/F3/F4 (interviewer-administered) — label from-uat-round-4-capi-2026-06
A16: R5 | B16: CAPI F1/F3/F4 — label from-uat-round-5-2026-06
A18: Status legend
A19: Fixed | B19: Issue resolved / fix built + deployed (GitHub: closed as completed).
A20: Deferred | B20: Closed as not-planned: duplicate, cosmetic, design decision, or parked for ASPSI input.
A21: Reported via = UAT form | B21: Filed through the GitHub UAT feedback template (label uat-feedback). 'Direct' = logged during triage. NOTE: the form label was applied mainly in R4, so this flag UNDERCOUNTS tester findings in R1-R3 / R5 — every round-tagged ticket is a UAT-round finding regardless of this flag.
A23: Notes
A24: • All issues are currently closed (0 open). Lifecycle: Raised (created date) -> Triaged + fixed -> Closed (closed date).
A25: • 'Deferred' tickets do not indicate failure — most are cosmetic, duplicate, or ASPSI-owned (translations / spec decisions) tracked separately.
A26: • A closed ticket can reopen on a stale-build desk-test failure (remove + re-add the CSEntry app to refresh).
A27: • Authoritative per-round narrative: see deliverables/CSPro/CAPI-UAT-Round-5-Closeout-2026-06-29.md and the scrum sprint records.

Sheet Summary by Round
A1: UAT Summary — tickets by round
A2: Counts are live formulas over the 'UAT Tickets' sheet (COUNTIF / COUNTIFS).
A4: Round | B4: Phase | C4: Window (raised → closed) | D4: Tickets raised | E4: Fixed | F4: Deferred | G4: Via UAT form | H4: F1 | I4: F3 | J4: F4 | K4: F2 PWA | L4: F2 Admin | M4: CSWeb
A5: R1 | B5: F2 PWA (HCW self-admin) | C5: 2026-04-23 -> 2026-04-25 | D5: =COUNTIF('UAT Tickets'!$A:$A,A5) -> 11 | E5: =COUNTIFS('UAT Tickets'!$A:$A,A5,'UAT Tickets'!$L:$L,"Fixed") -> 11 | F5: =COUNTIFS('UAT Tickets'!$A:$A,A5,'UAT Tickets'!$L:$L,"Deferred") -> 0 | G5: =COUNTIFS('UAT Tickets'!$A:$A,A5,'UAT Tickets'!$I:$I,"UAT form") -> 0 | H5: =COUNTIFS('UAT Tickets'!$A:$A,A5,'UAT Tickets'!$C:$C,"F1 — Facility Head") -> 0 | I5: =COUNTIFS('UAT Tickets'!$A:$A,A5,'UAT Tickets'!$C:$C,"F3 — Patient") -> 0 | J5: =COUNTIFS('UAT Tickets'!$A:$A,A5,'UAT Tickets'!$C:$C,"F4 — Household") -> 0 | K5: =COUNTIFS('UAT Tickets'!$A:$A,A5,'UAT Tickets'!$C:$C,"F2 — HCW (PWA)") -> 11 | L5: =COUNTIFS('UAT Tickets'!$A:$A,A5,'UAT Tickets'!$C:$C,"F2 Admin Portal") -> 0 | M5: =COUNTIFS('UAT Tickets'!$A:$A,A5,'UAT Tickets'!$C:$C,"CSWeb") -> 0
A6: R2 | B6: F2 PWA (HCW self-admin) | C6: 2026-04-25 -> 2026-05-09 | D6: =COUNTIF('UAT Tickets'!$A:$A,A6) -> 52 | E6: =COUNTIFS('UAT Tickets'!$A:$A,A6,'UAT Tickets'!$L:$L,"Fixed") -> 50 | F6: =COUNTIFS('UAT Tickets'!$A:$A,A6,'UAT Tickets'!$L:$L,"Deferred") -> 2 | G6: =COUNTIFS('UAT Tickets'!$A:$A,A6,'UAT Tickets'!$I:$I,"UAT form") -> 0 | H6: =COUNTIFS('UAT Tickets'!$A:$A,A6,'UAT Tickets'!$C:$C,"F1 — Facility Head") -> 0 | I6: =COUNTIFS('UAT Tickets'!$A:$A,A6,'UAT Tickets'!$C:$C,"F3 — Patient") -> 0 | J6: =COUNTIFS('UAT Tickets'!$A:$A,A6,'UAT Tickets'!$C:$C,"F4 — Household") -> 0 | K6: =COUNTIFS('UAT Tickets'!$A:$A,A6,'UAT Tickets'!$C:$C,"F2 — HCW (PWA)") -> 19 | L6: =COUNTIFS('UAT Tickets'!$A:$A,A6,'UAT Tickets'!$C:$C,"F2 Admin Portal") -> 33 | M6: =COUNTIFS('UAT Tickets'!$A:$A,A6,'UAT Tickets'!$C:$C,"CSWeb") -> 0
A7: R3 | B7: F2 PWA (HCW self-admin) | C7: 2026-04-25 -> 2026-06-05 | D7: =COUNTIF('UAT Tickets'!$A:$A,A7) -> 35 | E7: =COUNTIFS('UAT Tickets'!$A:$A,A7,'UAT Tickets'!$L:$L,"Fixed") -> 33 | F7: =COUNTIFS('UAT Tickets'!$A:$A,A7,'UAT Tickets'!$L:$L,"Deferred") -> 2 | G7: =COUNTIFS('UAT Tickets'!$A:$A,A7,'UAT Tickets'!$I:$I,"UAT form") -> 0 | H7: =COUNTIFS('UAT Tickets'!$A:$A,A7,'UAT Tickets'!$C:$C,"F1 — Facility Head") -> 0 | I7: =COUNTIFS('UAT Tickets'!$A:$A,A7,'UAT Tickets'!$C:$C,"F3 — Patient") -> 0 | J7: =COUNTIFS('UAT Tickets'!$A:$A,A7,'UAT Tickets'!$C:$C,"F4 — Household") -> 0 | K7: =COUNTIFS('UAT Tickets'!$A:$A,A7,'UAT Tickets'!$C:$C,"F2 — HCW (PWA)") -> 35 | L7: =COUNTIFS('UAT Tickets'!$A:$A,A7,'UAT Tickets'!$C:$C,"F2 Admin Portal") -> 0 | M7: =COUNTIFS('UAT Tickets'!$A:$A,A7,'UAT Tickets'!$C:$C,"CSWeb") -> 0
A8: R4 | B8: CAPI (F1/F3/F4 interviewer) | C8: 2026-06-12 -> 2026-06-21 | D8: =COUNTIF('UAT Tickets'!$A:$A,A8) -> 204 | E8: =COUNTIFS('UAT Tickets'!$A:$A,A8,'UAT Tickets'!$L:$L,"Fixed") -> 199 | F8: =COUNTIFS('UAT Tickets'!$A:$A,A8,'UAT Tickets'!$L:$L,"Deferred") -> 5 | G8: =COUNTIFS('UAT Tickets'!$A:$A,A8,'UAT Tickets'!$I:$I,"UAT form") -> 96 | H8: =COUNTIFS('UAT Tickets'!$A:$A,A8,'UAT Tickets'!$C:$C,"F1 — Facility Head") -> 28 | I8: =COUNTIFS('UAT Tickets'!$A:$A,A8,'UAT Tickets'!$C:$C,"F3 — Patient") -> 38 | J8: =COUNTIFS('UAT Tickets'!$A:$A,A8,'UAT Tickets'!$C:$C,"F4 — Household") -> 93 | K8: =COUNTIFS('UAT Tickets'!$A:$A,A8,'UAT Tickets'!$C:$C,"F2 — HCW (PWA)") -> 0 | L8: =COUNTIFS('UAT Tickets'!$A:$A,A8,'UAT Tickets'!$C:$C,"F2 Admin Portal") -> 0 | M8: =COUNTIFS('UAT Tickets'!$A:$A,A8,'UAT Tickets'!$C:$C,"CSWeb") -> 0
A9: R5 | B9: CAPI (F1/F3/F4 interviewer) | C9: 2026-06-21 -> 2026-06-27 | D9: =COUNTIF('UAT Tickets'!$A:$A,A9) -> 79 | E9: =COUNTIFS('UAT Tickets'!$A:$A,A9,'UAT Tickets'!$L:$L,"Fixed") -> 78 | F9: =COUNTIFS('UAT Tickets'!$A:$A,A9,'UAT Tickets'!$L:$L,"Deferred") -> 1 | G9: =COUNTIFS('UAT Tickets'!$A:$A,A9,'UAT Tickets'!$I:$I,"UAT form") -> 4 | H9: =COUNTIFS('UAT Tickets'!$A:$A,A9,'UAT Tickets'!$C:$C,"F1 — Facility Head") -> 5 | I9: =COUNTIFS('UAT Tickets'!$A:$A,A9,'UAT Tickets'!$C:$C,"F3 — Patient") -> 39 | J9: =COUNTIFS('UAT Tickets'!$A:$A,A9,'UAT Tickets'!$C:$C,"F4 — Household") -> 27 | K9: =COUNTIFS('UAT Tickets'!$A:$A,A9,'UAT Tickets'!$C:$C,"F2 — HCW (PWA)") -> 2 | L9: =COUNTIFS('UAT Tickets'!$A:$A,A9,'UAT Tickets'!$C:$C,"F2 Admin Portal") -> 0 | M9: =COUNTIFS('UAT Tickets'!$A:$A,A9,'UAT Tickets'!$C:$C,"CSWeb") -> 0
A10: TOTAL | B10: all UAT rounds | D10: =SUM(D5:D9) -> 381 | E10: =SUM(E5:E9) -> 371 | F10: =SUM(F5:F9) -> 10 | G10: =SUM(G5:G9) -> 100 | H10: =SUM(H5:H9) -> 33 | I10: =SUM(I5:I9) -> 77 | J10: =SUM(J5:J9) -> 120 | K10: =SUM(K5:K9) -> 67 | ... M10: =SUM(M5:M9) -> 0

Sheet UAT Tickets
A1: UAT Tickets — raised, triaged, fixed (by round)
A3: Round | B3: Phase | C3: Instrument | D3: Issue # | E3: Title | F3: Type | G3: Sub-type | H3: Severity | I3: Reported via | J3: Raised | K3: Closed | L3: Resolution | M3: Disposition / note | N3: Link
A4: R1 | B4: F2 PWA (HCW self-admin) | C4: F2 — HCW (PWA) | D4: 1 | E4: How old are you as of your last birthday (in years)? | F4: Other | G4: validation | H4: Medium | I4: Direct | J4: 46135 | K4: 46137 | L4: Fixed | M4: Fixed (was pending tester verify at close) | N4: https://github.com/cplreyes/ASPSI-DOH-UHC-CAPI-Development/issues/1
A5: R1 | B5: F2 PWA (HCW self-admin) | C5: F2 — HCW (PWA) | D5: 2 | E5: What is your role at this health facility? | F5: Other | G5: ux | H5: Medium | I5: Direct | J5: 46135 | K5: 46137 | L5: Fixed | M5: Fixed (was pending tester verify at close) | N5: https://github.com/cplreyes/ASPSI-DOH-UHC-CAPI-Development/issues/2
A6: R1 | B6: F2 PWA (HCW self-admin) | C6: F2 — HCW (PWA) | D6: 3 | E6: In your current position, how many (months/years) have you worked at this health facility? | F6: Other | G6: validation | H6: Medium | I6: Direct | J6: 46135 | K6: 46137 | L6: Fixed | M6: Fixed (was pending tester verify at close) | N6: https://github.com/cplreyes/ASPSI-DOH-UHC-CAPI-Development/issues/3
A7: R1 | B7: F2 PWA (HCW self-admin) | C7: F2 — HCW (PWA) | D7: 4 | E7: How old are you as of your last birthday (in years)? | F7: Other | G7: validation | H7: Medium | I7: Direct | J7: 46135 | K7: 46137 | L7: Fixed | M7: Fixed (was pending tester verify at close) | N7: https://github.com/cplreyes/ASPSI-DOH-UHC-CAPI-Development/issues/4
A8: R1 | B8: F2 PWA (HCW self-admin) | C8: F2 — HCW (PWA) | D8: 5 | E8: In your current position, how many (months/years) have you worked at this health facility? | F8: Other | G8: validation | H8: Medium | I8: Direct | J8: 46135 | K8: 46137 | L8: Fixed | M8: Fixed (was pending tester verify at close) | N8: https://github.com/cplreyes/ASPSI-DOH-UHC-CAPI-Development/issues/5
A9: R1 | B9: F2 PWA (HCW self-admin) | C9: F2 — HCW (PWA) | D9: 6 | E9: Q12.Have you heard about Universal Health Care (UHC) prior to this survey? | F9: Other | G9: skip-logic | H9: High | I9: Direct | J9: 46135 | K9: 46137 | L9: Fixed | M9: Fixed (was pending tester verify at close) | N9: https://github.com/cplreyes/ASPSI-DOH-UHC-CAPI-Development/issues/6
A10: R1 | B10: F2 PWA (HCW self-admin) | C10: F2 — HCW (PWA) | D10: 8 | E10: Q25 – Conditional Logic Restriction Issue | F10: Other | G10: skip-logic | H10: High | I10: Direct | J10: 46136 | K10: 46137 | L10: Fixed | M10: Fixed (was pending tester verify at close) | N10: https://github.com/cplreyes/ASPSI-DOH-UHC-CAPI-Development/issues/8
A11: R1 | B11: F2 PWA (HCW self-admin) | C11: F2 — HCW (PWA) | D11: 10 | E11: Auto-Advance Issue on Required Questions | F11: Bug | H11: Critical | I11: Direct | J11: 46136 | K11: 46137 | L11: Fixed | M11: Fixed (was pending tester verify at close) | N11: https://github.com/cplreyes/ASPSI-DOH-UHC-CAPI-Development/issues/10
A12: R1 | B12: F2 PWA (HCW self-admin) | C12: F2 — HCW (PWA) | D12: 11 | E12: Section Applicability Issue (Section G) | F12: Other | G12: skip-logic | H12: High | I12: Direct | J12: 46136 | K12: 46137 | L12: Fixed | M12: Fixed (was pending tester verify at close) | N12: https://github.com/cplreyes/ASPSI-DOH-UHC-CAPI-Development/issues/11
A13: R1 | B13: F2 PWA (HCW self-admin) | C13: F2 — HCW (PWA) | D13: 12 | E13: Test Scenario Observations | F13: Other | G13: sync | H13: High | I13: Direct | J13: 46136 | K13: 46137 | L13: Fixed | M13: Fixed (was pending tester verify at close) | N13: https://github.com/cplreyes/ASPSI-DOH-UHC-CAPI-Development/issues/12
A14: R1 | B14: F2 PWA (HCW self-admin) | C14: F2 — HCW (PWA) | D14: 13 | E14: Mid-section skip logic — conditional jumps not enforced (Q34/Q38/Q39/Q44/Q48/Q53/Q69/Q70/Q87/Q88) | F14: Other | G14: skip-logic | H14: High | I14: Direct | J14: 46137 | K14: 46137 | L14: Fixed | M14: Fixed (was pending tester verify at close) | N14: https://github.com/cplreyes/ASPSI-DOH-UHC-CAPI-Development/issues/13
A15: R2 | B15: F2 PWA (HCW self-admin) | C15: F2 — HCW (PWA) | D15: 14 | E15: Q9 Month(s) field should be optional, not required | F15: Other | G15: validation | H15: Medium | I15: Direct | J15: 46137 | K15: 46137 | L15: Fixed | M15: Fixed (was pending tester verify at close) | N15: https://github.com/cplreyes/ASPSI-DOH-UHC-CAPI-Development/issues/14
A16: R2 | B16: F2 PWA (HCW self-admin) | C16: F2 — HCW (PWA) | D16: 15 | E16: Cannot proceed when gating question answered No (Q12, Q31, similar) | F16: Other | G16: skip-logic | H16: Critical | I16: Direct | J16: 46137 | K16: 46137 | L16: Fixed | M16: Fixed (was pending tester verify at close) | N16: https://github.com/cplreyes/ASPSI-DOH-UHC-CAPI-Development/issues/15
A17: R2 | B17: F2 PWA (HCW self-admin) | C17: F2 — HCW (PWA) | D17: 16 | E17: I don't know option should be exclusive in multi-select questions | F17: Other | G17: ux | H17: Medium | I17: Direct | J17: 46137 | K17: 46143 | L17: Fixed | M17: Fixed (was pending tester verify at close) | N17: https://github.com/cplreyes/ASPSI-DOH-UHC-CAPI-Development/issues/16
A18: R2 | B18: F2 PWA (HCW self-admin) | C18: F2 — HCW (PWA) | D18: 17 | E18: All of the above should auto-select all other options | F18: Other | G18: ux | H18: Medium | I18: Direct | J18: 46137 | K18: 46143 | L18: Fixed | M18: Fixed (was pending tester verify at close) | N18: https://github.com/cplreyes/ASPSI-DOH-UHC-CAPI-Development/issues/17
A19: R2 | B19: F2 PWA (HCW self-admin) | C19: F2 — HCW (PWA) | D19: 18 | E19: Render scale-style questions as a 2-way matrix instead of one-by-one | F19: Enhancement | G19: ux | H19: Low | I19: Direct | J19: 46137 | K19: 46143 | L19: Fixed | M19: Fixed (was pending tester verify at close) | N19: https://github.com/cplreyes/ASPSI-DOH-UHC-CAPI-Development/issues/18
A20: R2 | B20: F2 PWA (HCW self-admin) | C20: F2 — HCW (PWA) | D20: 108 | E20: (A.1.E2) 5.1 Token-paste enrollment | F20: Bug | G20: ux | H20: Low | I20: Direct | J20: 46149 | K20: 46151 | L20: Fixed | N20: https://github.com/cplreyes/ASPSI-DOH-UHC-CAPI-Development/issues/108
A21: R2 | B21: F2 PWA (HCW self-admin) | C21: F2 — HCW (PWA) | D21: 109 | E21: (A.1.E3) 5.1 Token-paste enrollment | F21: Bug | G21: sync | H21: Low | I21: Direct | J21: 46149 | K21: 46151 | L21: Fixed | N21: https://github.com/cplreyes/ASPSI-DOH-UHC-CAPI-Development/issues/109
A22: R2 | B22: F2 PWA (HCW self-admin) | C22: F2 — HCW (PWA) | D22: 110 | E22: (A.2.E8) Q9 - 5.2 Section A — Healthcare Worker Profile (Q1–Q11) | F22: Bug | G22: validation | H22: Medium | I22: Direct | J22: 46149 | K22: 46151 | L22: Fixed | N22: https://github.com/cplreyes/ASPSI-DOH-UHC-CAPI-Development/issues/110
A23: R2 | B23: F2 PWA (HCW self-admin) | C23: F2 — HCW (PWA) | D23: 111 | E23: (B.E1) 5.3 Section B — UHC Awareness (Q25) | F23: Other | I23: Direct | J23: 46149 | K23: 46150 | L23: Fixed | N23: https://github.com/cplreyes/ASPSI-DOH-UHC-CAPI-Development/issues/111
A24: R2 | B24: F2 PWA (HCW self-admin) | C24: F2 — HCW (PWA) | D24: 112 | E24: 5. (B.E2) 5.3 Section B — UHC Awareness (Q25) | F24: Other | G24: validation | H24: High | I24: Direct | J24: 46149 | K24: 46151 | L24: Fixed | N24: https://github.com/cplreyes/ASPSI-DOH-UHC-CAPI-Development/issues/112
A25: R2 | B25: F2 PWA (HCW self-admin) | C25: F2 — HCW (PWA) | D25: 114 | E25: (C.E1) 5.4 Section C — YAKAP/Konsulta (Q31–Q40, role-gated) | F25: Bug | G25: skip-logic | H25: Critical | I25: Direct | J25: 46150 | K25: 46151 | L25: Fixed | N25: https://github.com/cplreyes/ASPSI-DOH-UHC-CAPI-Development/issues/114
A26: R2 | B26: F2 PWA (HCW self-admin) | C26: F2 — HCW (PWA) | D26: 115 | E26: (C.E2) 5.4 Section C — YAKAP/Konsulta (Q31–Q40, role-gated) | F26: Bug | G26: skip-logic | H26: Medium | I26: Direct | J26: 46150 | K26: 46151 | L26: Fixed | N26: https://github.com/cplreyes/ASPSI-DOH-UHC-CAPI-Development/issues/115
A27: R2 | B27: F2 PWA (HCW self-admin) | C27: F2 — HCW (PWA) | D27: 116 | E27: (Q44) 5.5 Section D — NBB/ZBB Awareness (Q41–Q47, role-gated) | F27: Bug | G27: skip-logic | H27: High | I27: Direct | J27: 46150 | K27: 46151 | L27: Fixed | N27: https://github.com/cplreyes/ASPSI-DOH-UHC-CAPI-Development/issues/116
A28: R2 | B28: F2 PWA (HCW self-admin) | C28: F2 — HCW (PWA) | D28: 117 | E28: Section E1 and E2 | F28: Enhancement | G28: skip-logic | I28: Direct | J28: 46150 | K28: 46151 | L28: Fixed | N28: https://github.com/cplreyes/ASPSI-DOH-UHC-CAPI-Development/issues/117
A29: R2 | B29: F2 PWA (HCW self-admin) | C29: F2 — HCW (PWA) | D29: 118 | E29: Section G — back-nav loses answers at Q87/Q88 + X icon despite ✓ + redirect to F (KAP on Professional Setting, Charging, And Reimbursement) | F29: Bug | G29: skip-logic | H29: Critical | I29: Direct | J29: 46150 | K29: 46151 | L29: Fixed | N29: https://github.com/cplreyes/ASPSI-DOH-UHC-CAPI-Development/issues/118
A30: R2 | B30: F2 PWA (HCW self-admin) | C30: F2 — HCW (PWA) | D30: 119 | E30: 5.12 Section J — Job Satisfaction (Q98–Q125, two matrix grids + terminal branch) | F30: Bug | G30: skip-logic | H30: Critical | I30: Direct | J30: 46150 | K30: 46151 | L30: Fixed | N30: https://github.com/cplreyes/ASPSI-DOH-UHC-CAPI-Development/issues/119
A31: R2 | B31: F2 PWA (HCW self-admin) | C31: F2 — HCW (PWA) | D31: 120 | E31: 5.13 Submission + Sync | F31: Bug | G31: sync | H31: Medium | I31: Direct | J31: 46150 | K31: 46151 | L31: Fixed | N31: https://github.com/cplreyes/ASPSI-DOH-UHC-CAPI-Development/issues/120
A32: R2 | B32: F2 PWA (HCW self-admin) | C32: F2 — HCW (PWA) | D32: 121 | E32: Sync/Submission | F32: Bug | G32: sync | H32: Medium | I32: Direct | J32: 46150 | K32: 46151 | L32: Fixed | N32: https://github.com/cplreyes/ASPSI-DOH-UHC-CAPI-Development/issues/121
A33: R2 | B33: F2 PWA (HCW self-admin) | C33: F2 — HCW (PWA) | D33: 122 | E33: Sync + Submission | F33: Bug | G33: sync | H33: Critical | I33: Direct | J33: 46150 | K33: 46151 | L33: Fixed | N33: https://github.com/cplreyes/ASPSI-DOH-UHC-CAPI-Development/issues/122
A34: R2 | B34: F2 PWA (HCW self-admin) | C34: F2 Admin Portal | D34: 68 | E34: #4 – Reference: Admin Portal Layout | F34: Bug | H34: High | I34: Direct | J34: 46149 | K34: 46151 | L34: Fixed | M34: Fixed (was pending tester verify at close) | N34: https://github.com/cplreyes/ASPSI-DOH-UHC-CAPI-Development/issues/68
A35: R2 | B35: F2 PWA (HCW self-admin) | C35: F2 Admin Portal | D35: 69 | E35: 5.1 Login + session | F35: Bug | G35: ux | H35: Low | I35: Direct | J35: 46149 | K35: 46151 | L35: Fixed | M35: Fixed (was pending tester verify at close) | N35: https://github.com/cplreyes/ASPSI-DOH-UHC-CAPI-Development/issues/69
A36: R2 | B36: F2 PWA (HCW self-admin) | C36: F2 Admin Portal | D36: 70 | E36: Login + session | F36: Bug | I36: Direct | J36: 46149 | K36: 46151 | L36: Fixed | M36: Fixed (was pending tester verify at close) | N36: https://github.com/cplreyes/ASPSI-DOH-UHC-CAPI-Development/issues/70
A37: R2 | B37: F2 PWA (HCW self-admin) | C37: F2 Admin Portal | D37: 71 | E37: Login + session | F37: Bug | I37: Direct | J37: 46149 | K37: 46151 | L37: Fixed | M37: Fixed (was pending tester verify at close) | N37: https://github.com/cplreyes/ASPSI-DOH-UHC-CAPI-Development/issues/71
A38: R2 | B38: F2 PWA (HCW self-admin) | C38: F2 Admin Portal | D38: 72 | E38: Login + session | F38: Bug | I38: Direct | J38: 46149 | K38: 46151 | L38: Fixed | M38: Fixed (was pending tester verify at close) | N38: https://github.com/cplreyes/ASPSI-DOH-UHC-CAPI-Development/issues/72
A39: R2 | B39: F2 PWA (HCW self-admin) | C39: F2 Admin Portal | D39: 78 | E39: Data dashboard — Responses sub-tab - Other Observation | F39: Bug | I39: Direct | J39: 46149 | K39: 46151 | L39: Fixed | M39: Fixed (was pending tester verify at close) | N39: https://github.com/cplreyes/ASPSI-DOH-UHC-CAPI-Development/issues/78
A40: R2 | B40: F2 PWA (HCW self-admin) | C40: F2 Admin Portal | D40: 79 | E40: 5.3 Data dashboard — Audit sub-tab | F40: Bug | I40: Direct | J40: 46149 | K40: 46151 | L40: Fixed | M40: Fixed (was pending tester verify at close) | N40: https://github.com/cplreyes/ASPSI-DOH-UHC-CAPI-Development/issues/79
A41: R2 | B41: F2 PWA (HCW self-admin) | C41: F2 Admin Portal | D41: 80 | E41: Data dashboard — Audit sub-tab | F41: Bug | I41: Direct | J41: 46149 | K41: 46151 | L41: Fixed | M41: Fixed (was pending tester verify at close) | N41: https://github.com/cplreyes/ASPSI-DOH-UHC-CAPI-Development/issues/80
...

Sheet All Issues
A1: All GitHub issues (full register, incl. non-UAT dev/backlog)
A3: Round | B3: Phase | C3: Instrument | D3: Issue # | E3: Title | F3: Type | G3: Sub-type | H3: Severity | I3: Reported via | J3: Raised | K3: Closed | L3: Resolution | M3: Disposition / note | N3: Link
A4: R1 | B4: F2 PWA (HCW self-admin) | C4: F2 — HCW (PWA) | D4: 1 | E4: How old are you as of your last birthday (in years)? | F4: Other | G4: validation | H4: Medium | I4: Direct | J4: 46135 | K4: 46137 | L4: Fixed | M4: Fixed (was pending tester verify at close) | N4: https://github.com/cplreyes/ASPSI-DOH-UHC-CAPI-Development/issues/1
A5: R1 | B5: F2 PWA (HCW self-admin) | C5: F2 — HCW (PWA) | D5: 2 | E5: What is your role at this health facility? | F5: Other | G5: ux | H5: Medium | I5: Direct | J5: 46135 | K5: 46137 | L5: Fixed | M5: Fixed (was pending tester verify at close) | N5: https://github.com/cplreyes/ASPSI-DOH-UHC-CAPI-Development/issues/2
A6: R1 | B6: F2 PWA (HCW self-admin) | C6: F2 — HCW (PWA) | D6: 3 | E6: In your current position, how many (months/years) have you worked at this health facility? | F6: Other | G6: validation | H6: Medium | I6: Direct | J6: 46135 | K6: 46137 | L6: Fixed | M6: Fixed (was pending tester verify at close) | N6: https://github.com/cplreyes/ASPSI-DOH-UHC-CAPI-Development/issues/3
A7: R1 | B7: F2 PWA (HCW self-admin) | C7: F2 — HCW (PWA) | D7: 4 | E7: How old are you as of your last birthday (in years)? | F7: Other | G7: validation | H7: Medium | I7: Direct | J7: 46135 | K7: 46137 | L7: Fixed | M7: Fixed (was pending tester verify at close) | N7: https://github.com/cplreyes/ASPSI-DOH-UHC-CAPI-Development/issues/4
A8: R1 | B8: F2 PWA (HCW self-admin) | C8: F2 — HCW (PWA) | D8: 5 | E8: In your current position, how many (months/years) have you worked at this health facility? | F8: Other | G8: validation | H8: Medium | I8: Direct | J8: 46135 | K8: 46137 | L8: Fixed | M8: Fixed (was pending tester verify at close) | N8: https://github.com/cplreyes/ASPSI-DOH-UHC-CAPI-Development/issues/5
A9: R1 | B9: F2 PWA (HCW self-admin) | C9: F2 — HCW (PWA) | D9: 6 | E9: Q12.Have you heard about Universal Health Care (UHC) prior to this survey? | F9: Other | G9: skip-logic | H9: High | I9: Direct | J9: 46135 | K9: 46137 | L9: Fixed | M9: Fixed (was pending tester verify at close) | N9: https://github.com/cplreyes/ASPSI-DOH-UHC-CAPI-Development/issues/6
A10: (none) | C10: General / Dev | D10: 7 | E10: Q9 – Months Input Validation | F10: Duplicate | I10: Direct | J10: 46136 | K10: 46137 | L10: Deferred | M10: Duplicate | N10: https://github.com/cplreyes/ASPSI-DOH-UHC-CAPI-Development/issues/7
A11: R1 | B11: F2 PWA (HCW self-admin) | C11: F2 — HCW (PWA) | D11: 8 | E11: Q25 – Conditional Logic Restriction Issue | F11: Other | G11: skip-logic | H11: High | I11: Direct | J11: 46136 | K11: 46137 | L11: Fixed | M11: Fixed (was pending tester verify at close) | N11: https://github.com/cplreyes/ASPSI-DOH-UHC-CAPI-Development/issues/8
A12: (none) | C12: General / Dev | D12: 9 | E12: Skip Logic / Navigation Issues | F12: Duplicate | I12: Direct | J12: 46136 | K12: 46137 | L12: Deferred | M12: Duplicate | N12: https://github.com/cplreyes/ASPSI-DOH-UHC-CAPI-Development/issues/9
A13: R1 | B13: F2 PWA (HCW self-admin) | C13: F2 — HCW (PWA) | D13: 10 | E13: Auto-Advance Issue on Required Questions | F13: Bug | H13: Critical | I13: Direct | J13: 46136 | K13: 46137 | L13: Fixed | M13: Fixed (was pending tester verify at close) | N13: https://github.com/cplreyes/ASPSI-DOH-UHC-CAPI-Development/issues/10
A14: R1 | B14: F2 PWA (HCW self-admin) | C14: F2 — HCW (PWA) | D14: 11 | E14: Section Applicability Issue (Section G) | F14: Other | G14: skip-logic | H14: High | I14: Direct | J14: 46136 | K14: 46137 | L14: Fixed | M14: Fixed (was pending tester verify at close) | N14: https://github.com/cplreyes/ASPSI-DOH-UHC-CAPI-Development/issues/11
A15: R1 | B15: F2 PWA (HCW self-admin) | C15: F2 — HCW (PWA) | D15: 12 | E15: Test Scenario Observations | F15: Other | G15: sync | H15: High | I15: Direct | J15: 46136 | K15: 46137 | L15: Fixed | M15: Fixed (was pending tester verify at close) | N15: https://github.com/cplreyes/ASPSI-DOH-UHC-CAPI-Development/issues/12
A16: R1 | B16: F2 PWA (HCW self-admin) | C16: F2 — HCW (PWA) | D16: 13 | E16: Mid-section skip logic — conditional jumps not enforced (Q34/Q38/Q39/Q44/Q48/Q53/Q69/Q70/Q87/Q88) | F16: Other | G16: skip-logic | H16: High | I16: Direct | J16: 46137 | K16: 46137 | L16: Fixed | M16: Fixed (was pending tester verify at close) | N16: https://github.com/cplreyes/ASPSI-DOH-UHC-CAPI-Development/issues/13
A17: R2 | B17: F2 PWA (HCW self-admin) | C17: F2 — HCW (PWA) | D17: 14 | E17: Q9 Month(s) field should be optional, not required | F17: Other | G17: validation | H17: Medium | I17: Direct | J17: 46137 | K17: 46137 | L17: Fixed | M17: Fixed (was pending tester verify at close) | N17: https://github.com/cplreyes/ASPSI-DOH-UHC-CAPI-Development/issues/14
A18: R2 | B18: F2 PWA (HCW self-admin) | C18: F2 — HCW (PWA) | D18: 15 | E18: Cannot proceed when gating question answered No (Q12, Q31, similar) | F18: Other | G18: skip-logic | H18: Critical | I18: Direct | J18: 46137 | K18: 46137 | L18: Fixed | M18: Fixed (was pending tester verify at close) | N18: https://github.com/cplreyes/ASPSI-DOH-UHC-CAPI-Development/issues/15
A19: R2 | B19: F2 PWA (HCW self-admin) | C19: F2 — HCW (PWA) | D19: 16 | E19: I don't know option should be exclusive in multi-select questions | F19: Other | G19: ux | H19: Medium | I19: Direct | J19: 46137 | K19: 46143 | L19: Fixed | M19: Fixed (was pending tester verify at close) | N19: https://github.com/cplreyes/ASPSI-DOH-UHC-CAPI-Development/issues/16
A20: R2 | B20: F2 PWA (HCW self-admin) | C20: F2 — HCW (PWA) | D20: 17 | E20: All of the above should auto-select all other options | F20: Other | G20: ux | H20: Medium | I20: Direct | J20: 46137 | K20: 46143 | L20: Fixed | M20: Fixed (was pending tester verify at close) | N20: https://github.com/cplreyes/ASPSI-DOH-UHC-CAPI-Development/issues/17
A21: R2 | B21: F2 PWA (HCW self-admin) | C21: F2 — HCW (PWA) | D21: 18 | E21: Render scale-style questions as a 2-way matrix instead of one-by-one | F21: Enhancement | G21: ux | H21: Low | I21: Direct | J21: 46137 | K21: 46143 | L21: Fixed | M21: Fixed (was pending tester verify at close) | N21: https://github.com/cplreyes/ASPSI-DOH-UHC-CAPI-Development/issues/18
A22: R3 | B22: F2 PWA (HCW self-admin) | C22: F2 — HCW (PWA) | D22: 19 | E22: Q4/Q9/Q10/Q11 — raw Zod error 'Expected number, received nan' leaks to UI | F22: Other | G22: validation | H22: High | I22: Direct | J22: 46137 | K22: 46143 | L22: Fixed | N22: https://github.com/cplreyes/ASPSI-DOH-UHC-CAPI-Development/issues/19
A23: R3 | B23: F2 PWA (HCW self-admin) | C23: F2 — HCW (PWA) | D23: 20 | E23: Inverted heading hierarchy — page H1 (18px) smaller than section H2 (24px) | F23: Other | G23: visual | H23: High | I23: Direct | J23: 46137 | K23: 46143 | L23: Fixed | N23: https://github.com/cplreyes/ASPSI-DOH-UHC-CAPI-Development/issues/20
A24: R3 | B24: F2 PWA (HCW self-admin) | C24: F2 — HCW (PWA) | D24: 21 | E24: Form layout pushed off-center on viewports ≥1600px | F24: Other | G24: visual | H24: High | I24: Direct | J24: 46137 | K24: 46143 | L24: Fixed | N24: https://github.com/cplreyes/ASPSI-DOH-UHC-CAPI-Development/issues/21
A25: R3 | B25: F2 PWA (HCW self-admin) | C25: F2 — HCW (PWA) | D25: 22 | E25: Disabled buttons fail WCAG AA contrast (opacity:0.5 on teal → ~2:1) | F25: Other | G25: visual | H25: High | I25: Direct | J25: 46137 | K25: 46143 | L25: Fixed | N25: https://github.com/cplreyes/ASPSI-DOH-UHC-CAPI-Development/issues/22
A26: R3 | B26: F2 PWA (HCW self-admin) | C26: F2 — HCW (PWA) | D26: 23 | E26: Default button height 32px below 44px tablet touch-target minimum | F26: Other | G26: ux | H26: Medium | I26: Direct | J26: 46137 | K26: 46143 | L26: Fixed | N26: https://github.com/cplreyes/ASPSI-DOH-UHC-CAPI-Development/issues/23
A27: R3 | B27: F2 PWA (HCW self-admin) | C27: F2 — HCW (PWA) | D27: 24 | E27: No visible focus ring on keyboard Tab navigation | F27: Other | G27: a11y | H27: Medium | I27: Direct | J27: 46137 | K27: 46143 | L27: Fixed | N27: https://github.com/cplreyes/ASPSI-DOH-UHC-CAPI-Development/issues/24
A28: R3 | B28: F2 PWA (HCW self-admin) | C28: F2 — HCW (PWA) | D28: 25 | E28: Q1_3 Middle Initial should be optional (apply same fix pattern as #14) | F28: Other | G28: validation | H28: Low | I28: Direct | J28: 46137 | K28: 46143 | L28: Fixed | N28: https://github.com/cplreyes/ASPSI-DOH-UHC-CAPI-Development/issues/25
A29: R3 | B29: F2 PWA (HCW self-admin) | C29: F2 — HCW (PWA) | D29: 26 | E29: Inconsistent Other label casing Q2 comma form vs Q5 parens form | F29: Other | G29: ux | H29: Low | I29: Direct | J29: 46137 | K29: 46143 | L29: Fixed | N29: https://github.com/cplreyes/ASPSI-DOH-UHC-CAPI-Development/issues/26
A30: R3 | B30: F2 PWA (HCW self-admin) | C30: F2 — HCW (PWA) | D30: 27 | E30: Locked sidebar sections appear as enabled buttons in a11y tree | F30: Other | G30: a11y | H30: Low | I30: Direct | J30: 46137 | K30: 46143 | L30: Fixed | N30: https://github.com/cplreyes/ASPSI-DOH-UHC-CAPI-Development/issues/27
A31: R3 | B31: F2 PWA (HCW self-admin) | C31: F2 — HCW (PWA) | D31: 28 | E31: Test Facility present in seed/cached facility list (also on staging) | F31: Other | G31: ux | H31: Low | I31: Direct | J31: 46137 | K31: 46143 | L31: Fixed | N31: https://github.com/cplreyes/ASPSI-DOH-UHC-CAPI-Development/issues/28
A32: R3 | B32: F2 PWA (HCW self-admin) | C32: F2 — HCW (PWA) | D32: 29 | E32: Right-edge floating arrow indicator clips off-screen at 375px viewport | F32: Other | G32: visual | H32: Low | I32: Direct | J32: 46137 | K32: 46143 | L32: Fixed | N32: https://github.com/cplreyes/ASPSI-DOH-UHC-CAPI-Development/issues/29
A33: R3 | B33: F2 PWA (HCW self-admin) | C33: F2 — HCW (PWA) | D33: 30 | E33: Header subtitle low contrast uses --muted instead of --muted-foreground | F33: Other | G33: visual | H33: Low | I33: Direct | J33: 46137 | K33: 46143 | L33: Fixed | N33: https://github.com/cplreyes/ASPSI-DOH-UHC-CAPI-Development/issues/30
A34: R3 | B34: F2 PWA (HCW self-admin) | C34: F2 — HCW (PWA) | D34: 33 | E34: Section F/G multi-select state pollution: selections unchecked when answering other questions | F34: Other | G34: ux | H34: High | I34: Direct | J34: 46138 | K34: 46142 | L34: Fixed | N34: https://github.com/cplreyes/ASPSI-DOH-UHC-CAPI-Development/issues/33
A35: R3 | B35: F2 PWA (HCW self-admin) | C35: F2 — HCW (PWA) | D35: 34 | E35: Cloudflare Pages auto-deploy on staging push is not firing | F35: Other | H35: High | I35: Direct | J35: 46138 | K35: 46142 | L35: Fixed | N35: https://github.com/cplreyes/ASPSI-DOH-UHC-CAPI-Development/issues/34
A36: R3 | B36: F2 PWA (HCW self-admin) | C36: F2 — HCW (PWA) | D36: 35 | E36: Worker PBKDF2 hash defaults (600k iters) exceed Cloudflare Workers runtime cap (100k) | F36: Other | H36: Medium | I36: Direct | J36: 46138 | K36: 46143 | L36: Fixed | N36: https://github.com/cplreyes/ASPSI-DOH-UHC-CAPI-Development/issues/35
A37: R3 | B37: F2 PWA (HCW self-admin) | C37: F2 — HCW (PWA) | D37: 45 | E37: F2 PWA `.env.local` stale — missing `VITE_F2_PROXY_URL` silently breaks staging build | F37: Other | H37: High | I37: Direct | J37: 46142 | K37: 46143 | L37: Fixed | N37: https://github.com/cplreyes/ASPSI-DOH-UHC-CAPI-Development/issues/45
A38: R3 | B38: F2 PWA (HCW self-admin) | C38: F2 — HCW (PWA) | D38: 46 | E38: F2 PWA enrollment: Enroll button no-ops on real-browser staging (verified token, no IDB write, no error) | F38: Other | H38: High | I38: Direct | J38: 46142 | K38: 46143 | L38: Fixed | N38: https://github.com/cplreyes/ASPSI-DOH-UHC-CAPI-Development/issues/46
A39: R3 | B39: F2 PWA (HCW self-admin) | C39: F2 — HCW (PWA) | D39: 52 | E39: EnrollmentScreen: Refresh button uses pre-enrollment deviceToken (empty) instead of verified token | F39: Other | G39: ux | H39: Medium | I39: Direct | J39: 46143 | K39: 46143 | L39: Fixed | N39: https://github.com/cplreyes/ASPSI-DOH-UHC-CAPI-Development/issues/52
A40: (none) | C40: F2 — HCW (PWA) | D40: 55 | E40: F2 PWA QA delta — 2026-05-04 | F40: Other | I40: Direct | J40: 46146 | K40: 46147 | L40: Fixed | N40: https://github.com/cplreyes/ASPSI-DOH-UHC-CAPI-Development/issues/55
A41: (none) | C41: F2 Admin Portal | D41: 56 | E41: [E4-APRT-044] RBAC role-version cache stale-entry — revoked permissions persist up to 60 min | F41: Bug | G41: security | H41: High | I41: Direct | J41: 46147 | K41: 46151 | L41: Fixed | N41: https://github.com/cplreyes/ASPSI-DOH-UHC-CAPI-Development/issues/56
...
